Workbook

Sheet List of documents
A1: Name of the document | B1: Institution | C1: URL | D1: Authors | E1: Affiliates | F1: Sector | G1: Country | H1: Date | I1: Keywords | J1: Exclusion criteria | K1: Status | L1: Label | M1: MapAIE (ours) | N1: Jobin | O1: Fjeld | P1: Tidjon | Q1: Hagendorff | R1: Floridi | S1: Zeng (LAIP) | T1: Attard-Frost | U1: EP | V1: Algorithm watch | W1: CE | X1: Winfield | Y1: EthicalML GitHub | Z1: all sources | AA1: Checked by | AB1: Random
A2: A Unified Framework of Five Principles for AI in Society | B2: . | C2: https://hdsr.mitpress.mit.edu/pub/l0jsh9d1/release/8 | K2: Not included | L2: meta analysis | M2: =IF(LOWER(K2)="included", 1,0) -> 0 | X2: 1 | Z2: =SUM(N2:Y2) -> 1 | AA2: Maria
A3: AI Decolonial Manyfesto | B3: . | C3: https://manyfesto.ai/ | D3: Aarathi Krishnan, Angie Abdilla, A Jung Moon, Carlos Affonso Souza, Chelle Adamson, Eileen M. Lach, Farah Ghazal, Jessica Fjeld, Jennyfer Taylor, John C. Havens, Malavika Jayaram, Monique Morrow, Nagla Rizk, Paola Ricaurte Quijano, R. Buse Çetin, Raja Chatila, Ravit Dotan, Sabelo Mhlambi, Sara Jordan, Sarita Rosenstock | E3: . | F3: civil society | G3: international | H3: 2021 | I3: collective, decolonial, petition | K3: Not included | L3: not cited | M3: =IF(LOWER(K3)="included", 1,0) -> 0 | Z3: =SUM(N3:Y3) -> 0 | AA3: Maria | AB3: Should be included if was cited by anyone
A4: Asimov’s three laws of Robotics | B4: . | K4: Not included | L4: not accessible | M4: =IF(LOWER(K4)="included", 1,0) -> 0 | X4: 1 | Z4: =SUM(N4:Y4) -> 1 | AA4: Maria
A5: AI Index 2022 | B5: University of Stanford, SRI International, MIT, OpenAI, McKinsey Global Institute, Partnership on AI, Harvard University | C5: https://aiindex.stanford.edu/wp-content/uploads/2022/03/2022-AI-Index-Report_Master.pdf | F5: academia, private sector | G5: USA | H5: 2022 | K5: included | L5: SPI | M5: =IF(LOWER(K5)="included", 1,0) -> 1 | W5: 1 | Z5: =SUM(N5:Y5) -> 1 | AA5: Simon | AB5: 0.001920514
A6: 2030 Digital Compass: the European way for the Digital Decade | B6: European Commission | C6: https://eur-lex.europa.eu/legal-content/en/TXT/?uri=CELEX%3A52021DC0118 | F6: international organisation > EU institution | G6: international | H6: 09/03/2021 | K6: Included | L6: SPI | M6: =IF(LOWER(K6)="included", 1,0) -> 1 | W6: 1 | Z6: =SUM(N6:Y6) -> 1 | AA6: Maria | AB6: 0.002177313
A7: Global competition and convergence of AI Law | B7: Vrije Universiteit Brussel | C7: https://osf.io/preprints/socarxiv/j36ke/ | F7: academia | G7: Belgium | H7: 2021 | K7: included | L7: SPI field-specific | M7: =IF(LOWER(K7)="included", 1,0) -> 1 | W7: 1 | Z7: =SUM(N7:Y7) -> 1 | AA7: Simon | AB7: 0.005935097
A8: Six Principles of Artificial Intelligence | B8: . | C8: http://it.people.com.cn/n1/2020/0309/c1009-31622757.html | G8: China | K8: Not included | L8: not in english | M8: =IF(LOWER(K8)="included", 1,0) -> 0 | S8: 1 | Z8: =SUM(N8:Y8) -> 1 | AA8: Maria
A9: The #FreeAI Manifesto | B9: . | C9: https://github.com/freeai-manifesto/manifesto | D9: Maxim Orlovsky, Andrey Sobol | E9: . | F9: civil society | G9: international | H9: 2018 | I9: manifest machine-learning, neural-network, decentralized, manifesto, artificial-intelligence, neural-networks, floss, cognitive-science, decentralization, anarchy, anarchism, skynet, transhumanism, anarcho-capitalism, austrian-school-economics | K9: Not included | L9: not cited | M9: =IF(LOWER(K9)="included", 1,0) -> 0 | Z9: =SUM(N9:Y9) -> 0 | AA9: Maria | AB9: Should be included if was cited by anyone
A10: Technology rules? The advent of new technologies in the justice system | B10: House of Lords, Justice and Home affairs Committee (United Kingdom) | C10: https://publications.parliament.uk/pa/ld5802/ldselect/ldjusthom/180/180.pdf | F10: national authority | G10: UK | H10: 30/03/2022 | K10: Included | L10: SPI | M10: =IF(LOWER(K10)="included", 1,0) -> 1 | W10: 1 | Z10: =SUM(N10:Y10) -> 1 | AA10: Maria | AB10: 0.0075751195
A11: Algorithmic discrimination in Europe: Challenges and opportunities for gender equality and non-discrimination law | B11: European Commission (European network of legal experts in gender equality and non-discrimination) | C11: https://op.europa.eu/en/publication-detail/-/publication/082f1dbc-821d-11eb-9ac9-01aa75ed71a1 | F11: international organisation > EU institution | G11: EU | H11: 10/2020 | K11: Included | L11: SPI, issue-specific | M11: =IF(LOWER(K11)="included", 1,0) -> 1 | W11: 1 | Z11: =SUM(N11:Y11) -> 1 | AA11: Maria | AB11: 0.0076317783
A12: Universal Principles of Data Ethics | B12: Accenture | C12: https://www.accenture.com/t20160629T012639Z__w__/us-en/_acnmedia/PDF-24/Accenture-Universal-Principles-Data-Ethics.pdf new URL https://fr.scribd.com/document/450122018/Accenture-Universal-Principles-Data-Ethics# | G12: USA | K12: not included | L12: not ai ethics | M12: =IF(LOWER(K12)="included", 1,0) -> 0 | V12: 1 | W12: 1 | Z12: =SUM(N12:Y12) -> 2 | AA12: Tiphaine
A13: Responsible AI and robotics. An ethical framework. | B13: Accenture UK | C13: https://www.accenture.com/gb-en/company-responsible-ai-robotics | D13: . | E13: . | F13: private sector | G13: UK | H13: 2018 | K13: Not included | L13: initial url does not work and couldn't find new url | M13: =IF(LOWER(K13)="included", 1,0) -> 0 | N13: 1 | V13: 1 | W13: 1 | Z13: =SUM(N13:Y13) -> 3 | AA13: Maria
A14: AI Index 2019 | B14: University of Stanford, SRI International, MIT, OpenAI, McKinsey Global Institute, Partnership on AI, Harvard University | C14: https://hai.stanford.edu/sites/default/files/ai_index_2019_report.pdf | F14: academia, private sector | G14: USA | H14: 2019 | K14: included | L14: SPI | M14: =IF(LOWER(K14)="included", 1,0) -> 1 | W14: 1 | Z14: =SUM(N14:Y14) -> 1 | AA14: Simon | AB14: 0.010958856
A15: Artificial intelligence and the control of COVID-19 | B15: Council of Europe | C15: https://www.coe.int/en/web/artificial-intelligence/ai-and-control-of-covid-19-coronavirus | F15: international organisation > IGO | G15: EU | H15: 2020 | K15: included | L15: SPI issue-specific | M15: =IF(LOWER(K15)="included", 1,0) -> 1 | W15: 1 | Z15: =SUM(N15:Y15) -> 1 | AA15: Mel | AB15: 0.012365108
A16: Unified Ethical Frame for Big Data Analysis. IAF Big Data Ethics Initiative, Part A | B16: The Information Accountability Foundation | C16: https://bigdata.fpf.org/wp-content/uploads/2015/11/IAF-Unified-Ethical-Frame-for-Big-Data-Analysis.pdf | F16: international organisation > IGO | G16: UK | H16: 03/2015 | K16: included | L16: digital | M16: =IF(LOWER(K16)="included", 1,0) -> 1 | N16: 1 | V16: 1 | W16: 1 | Z16: =SUM(N16:Y16) -> 3 | AA16: Simon | AB16: 0.014377841
A17: Artificial Intelligence | B17: Samsung Research | C17: https://research.samsung.com/artificial-intelligence | F17: private sector | G17: South Korea | K17: included | L17: digital | M17: =IF(LOWER(K17)="included", 1,0) -> 1 | S17: 1 | Z17: =SUM(N17:Y17) -> 1 | AA17: Simon | AB17: 0.015867834
A18: Mapping Regulatory Proposals for AI in Europe | B18: AccessNow | C18: accessnow.org/wp-content/uploads/2018/11/mapping_regulatory_proposals_for_AI_in_EU.pdf | G18: USA | H18: 43405 | K18: not included | L18: meta-analysis | M18: =IF(LOWER(K18)="included", 1,0) -> 0 | W18: 1 | Z18: =SUM(N18:Y18) -> 1 | AA18: Tiphaine
A19: The EURON Roboethics Roadmap | B19: The European Robotics Research Network (EURON) | C19: http://www.roboethics.org/index_file/Roboethics%20Roadmap%20Rel.1.2.pdf | F19: academia | G19: EU | H19: 01/2007 | K19: included | L19: SPI digital | M19: =IF(LOWER(K19)="included", 1,0) -> 1 | U19: 1 | Z19: =SUM(N19:Y19) -> 1 | AA19: Simon | AB19: 0.018161725
A20: Ethics Canvas | B20: Adapt Center | C20: https://www.ethicscanvas.org/index.html | G20: Ireland | K20: not included | L20: not ai ethics | M20: =IF(LOWER(K20)="included", 1,0) -> 0 | P20: 1 | W20: 1 | Z20: =SUM(N20:Y20) -> 2 | AA20: Tiphaine
A21: Algorithm Data Ethics Label | B21: ADEL | C21: http://www.adel-label.com/adel/ | G21: France | K21: not included | L21: not in english | M21: =IF(LOWER(K21)="included", 1,0) -> 0 | V21: 1 | W21: 1 | Z21: =SUM(N21:Y21) -> 2 | AA21: Tiphaine
A22: Understanding Artificial Intelligence and Safety - A guide for the responsible design and implementation of AI systems in the public sector | B22: The Alan Turing Institute | C22: https://www.turing.ac.uk/sites/default/files/2019-06/understanding_artificial_intelligence_ethics_and_safety.pdf | F22: national authority, academia | G22: UK | H22: 2019 | K22: included | M22: =IF(LOWER(K22)="included", 1,0) -> 1 | S22: 1 | T22: 1 | V22: 1 | W22: 1 | Y22: 1 | Z22: =SUM(N22:Y22) -> 5 | AA22: Mel | AB22: 0.024087373
A23: Digital Ethics: A guide for professionals of the Digital Age | B23: CIGREF/Syntec Numérique | C23: https://www.cigref.fr/wp/wp-content/uploads/2019/02/Cigref-Syntec-Digital-Ethics-Guide-for-Professionals-of-Digital-Age-2018-October-EN.pdf | F23: civil society > other | G23: France | H23: 10/2018 | K23: included | L23: SPI digital | M23: =IF(LOWER(K23)="included", 1,0) -> 1 | V23: 1 | W23: 1 | Z23: =SUM(N23:Y23) -> 2 | AA23: Mel | AB23: 0.024125463
A24: Human Rights, Democracy, and the Rule of Law Assurance Framework for AI Systems: A proposal prepared for the Council of Europe’s Ad hoc Committee on Artificial Intelligence | B24: The Alan Turing Institute | C24: https://rm.coe.int/huderaf-coe-final-1-2752-6741-5300-v-1/1680a3f688 | F24: national authority, academia | G24: UK | H24: 2021 | K24: included | L24: SPI issue-specific | M24: =IF(LOWER(K24)="included", 1,0) -> 1 | W24: 1 | Z24: =SUM(N24:Y24) -> 1 | AA24: Simon | AB24: 0.035240019
A25: Study on AI Governance by Human Rights-Centred Design, Deliberation and Oversight | B25: University of Birmingham | C25: https://papers.ssrn.com/sol3/papers.cfm?abstract_id=3435011 | F25: academia | G25: UK | H25: 09/08/2019 | K25: included | L25: SPI digital | M25: =IF(LOWER(K25)="included", 1,0) -> 1 | W25: 1 | Z25: =SUM(N25:Y25) -> 1 | AA25: Simon | AB25: 0.035973615
A26: European ethical Charter on the use of Artificial Intelligence in judicial systems and their environment | B26: Council of Europe: European Commission for the efficiency of Justice (CEPEJ) | C26: https://rm.coe.int/ethical-charter-en-for-publication-4-december-2018/16808f699c | F26: international organisation > IGO | G26: EU | H26: 04/12/2018 | K26: included | L26: field-specific | M26: =IF(LOWER(K26)="included", 1,0) -> 1 | N26: 1 | O26: 1 | T26: 1 | V26: 1 | W26: 1 | X26: 1 | Z26: =SUM(N26:Y26) -> 6 | AA26: Mel | AB26: 0.037653615
A27: The Road to a Human-Centred Digital Society | B27: Centre on AI Technology for Humanking (AiTH) at NUS Business School | C27: https://drive.google.com/uc?export=download&id=1aRyqczni56ONA9PVExt2DrrJ1ATGKSu0 | D27: David De Cremer, Devesh Narayanan, Andreas Deppeler, Mahak Nagpal, Jack McGuire, Jess Zhang | E27: National University of Singapore | F27: academia | G27: Singapore | H27: 12/2021 | K27: included | M27: =IF(LOWER(K27)="included", 1,0) -> 1 | Z27: =SUM(N27:Y27) -> 0 | AA27: Mel | AB27: 0.045590909
A28: AI Roadmap | B28: AI Council (United Kingdom) | C28: https://assets.publishing.service.gov.uk/media/5ff3bc6e8fa8f53b76ccee23/AI_Council_AI_Roadmap.pdf | F28: national authority | G28: UK | H28: 01/2021 | K28: included | L28: SPI | M28: =IF(LOWER(K28)="included", 1,0) -> 1 | W28: 1 | Z28: =SUM(N28:Y28) -> 1 | AA28: Tiphaine | AB28: 0.046481623
A29: Growing the artificial intelligence industry in the UK | B29: Department for Digital, Culture, Media & Sport and Department for Business, Energy & Industrial Strategy (United Kingdom) | C29: https://www.gov.uk/government/publications/growing-the-artificial-intelligence-industry-in-the-uk | F29: national authority | G29: UK | H29: 15/10/2017 | K29: included | M29: =IF(LOWER(K29)="included", 1,0) -> 1 | W29: 1 | Z29: =SUM(N29:Y29) -> 1 | AA29: Tiphaine | AB29: 0.051865015
A30: AI Now 2017 Report | B30: AI Now Institute | C30: https://ainowinstitute.org/wp-content/uploads/2023/04/AI_Now_2017_Report.pdf | F30: civil society > NGO | G30: USA | H30: 2017 | K30: included | L30: SPI | M30: =IF(LOWER(K30)="included", 1,0) -> 1 | N30: 1 | Q30: 1 | Z30: =SUM(N30:Y30) -> 2 | AA30: Tiphaine | AB30: 0.055135916
A31: Algorithms in Decision Making | B31: Parliament Science and Technology Committee (United Kingdom) | C31: https://publications.parliament.uk/pa/cm201719/cmselect/cmsctech/351/351.pdf | F31: national authority | G31: UK | H31: 23/05/2018 | K31: included | L31: SPI | M31: =IF(LOWER(K31)="included", 1,0) -> 1 | W31: 1 | Z31: =SUM(N31:Y31) -> 1 | AA31: Simon | AB31: 0.055506496
A32: Thematic Reviews on 'Social Aspects of Digitalisation' (SPC) and 'Digitalisation and Robotisation of Work' (EMCO) - Endorsement of the joint key messages, 14411/18 | B32: Council of the European Union | C32: http://data.consilium.europa.eu/doc/document/ST-14411-2018-INIT/en/pdf | F32: international organisation > EU institution | G32: EU | H32: 19/11/2018 | K32: included | L32: SPI (study) | M32: =IF(LOWER(K32)="included", 1,0) -> 1 | W32: 1 | Z32: =SUM(N32:Y32) -> 1 | AA32: Tiphaine | AB32: 0.057972697
A33: Standards for AI Governance: International Standards to Enable Global Coordination in AI Research & Development | B33: Future of Humanity Institute, University of Oxford | C33: https://www.fhi.ox.ac.uk/wp-content/uploads/Standards_-FHI-Technical-Report.pdf | F33: academia | G33: international | H33: 04/2019 | K33: included | L33: field-specific | M33: =IF(LOWER(K33)="included", 1,0) -> 1 | W33: 1 | Z33: =SUM(N33:Y33) -> 1 | AA33: Tiphaine | AB33: 0.05949517
A34: Preparing the future of AI | B34: National Science and Technology Council (US) | C34: https://obamawhitehouse.archives.gov/sites/default/files/whitehouse_files/microsites/ostp/NSTC/preparing_for_the_future_of_ai.pdf | F34: national authority | G34: USA | H34: 10/2016 | K34: Included | L34: SPI | M34: =IF(LOWER(K34)="included", 1,0) -> 1 | W34: 1 | Z34: =SUM(N34:Y34) -> 1 | AA34: Maria | AB34: 0.062190447
A35: AI Now Report 2016. The Social and Economic Implications of Artificial Intelligence Technologies in the Near-Term | B35: AI Now Institute | C35: https://assets.ctfassets.net/8wprhhvnpfc0/3JOy5k4f1YSCQOi8MCCmA2/97010d04fbc7892662ce8b2469dc1601/AI_Now_2016_Report.pdf | F35: civil society > NGO | G35: USA | H35: 22/09/2016 | K35: included | L35: SPI | M35: =IF(LOWER(K35)="included", 1,0) -> 1 | N35: 1 | Q35: 1 | Z35: =SUM(N35:Y35) -> 2 | AA35: Tiphaine | AB35: 0.064955985
A36: Overview of National AI-Strategies | B36: AISOMA | C36: https://www.aisoma.de/wp-content/uploads/2021/01/Overview-of-National-AI-Strategies.pdf | G36: Germany | K36: not included | L36: meta-analysis | M36: =IF(LOWER(K36)="included", 1,0) -> 0 | W36: 1 | Z36: =SUM(N36:Y36) -> 1 | AA36: Tiphaine
A37: A toolkit for centering racial equity throughout data integration | B37: AISP | C37: https://aisp.upenn.edu/wp-content/uploads/2022/07/AISP-Toolkit_5.27.20.pdf | G37: USA | K37: not included | L37: tool | M37: =IF(LOWER(K37)="included", 1,0) -> 0 | P37: 1 | Z37: =SUM(N37:Y37) -> 1 | AA37: Tiphaine
A38: G20 AI Principles | B38: Ministry of Internal Affairs and Communications | C38: https://www.mofa.go.jp/policy/economy/g20_summit/osaka19/pdf/documents/en/annex_08.pdf | F38: national authority | G38: Japan | H38: 2019 | K38: included | M38: =IF(LOWER(K38)="included", 1,0) -> 1 | O38: 1 | Z38: =SUM(N38:Y38) -> 1 | AA38: Mel | AB38: 0.068610258
A39: Principles for the Governance of AI | B39: The Future Society Science Law and Society (SLS) Initiative | C39: https://thefuturesociety.org/principles-law-and-society-initiative/ | F39: civil society | G39: USA | H39: 15/07/2017 | K39: included | M39: =IF(LOWER(K39)="included", 1,0) -> 1 | N39: 1 | S39: 1 | U39: 1 | V39: 1 | W39: 1 | X39: 1 | Z39: =SUM(N39:Y39) -> 6 | AA39: Mel | AB39: 0.069249899
A40: 4 Steps to developing Responsible AI | B40: World Economic Forum (WEF) | C40: https://www.weforum.org/agenda/2019/06/4-steps-to-developing-responsible-ai/ | F40: civil society > NGO | G40: international | H40: 20/06/2019 | K40: included | L40: SPI | M40: =IF(LOWER(K40)="included", 1,0) -> 1 | W40: 1 | Z40: =SUM(N40:Y40) -> 1 | AA40: Simon | AB40: 0.070283627
...

Sheet Tableau croisé dynamique 3

Sheet Matthieu
A1: Title | B1: Institution | C1: URL | G1: Country | H1: Date | I1: Sector | N1: Maria | O1: Aina | P1: Simon
A2: AI Index 2022 | B2: University of Stanford, SRI International, MIT, OpenAI, McKinsey Global Institute, Partnership on AI, Harvard University | C2: https://aiindex.stanford.edu/wp-content/uploads/2022/03/2022-AI-Index-Report_Master.pdf | G2: USA | H2: 2022 | I2: Academia | M2: =IF(ISNUMBER(SEARCH(",",I2)),"multistakeholders",lower(I2)) -> academia | N2: =IF(LOWER(I2)=LOWER(Maria!L2),1,0) -> 1 | O2: =IF(LOWER(I2)=LOWER(Aina!N2),1,0) -> 0 | P2: =IF(LOWER(I2)=LOWER(Kappa!Y4),1,0) -> 0 | R2: Matthieu | T2: COUNTA de Sector | U2: SUM de Maria | V2: SUM de Aina | W2: SUM de Simon | X2: Maria | Y2: Aina | Z2: Simon
A3: 2030 Digital Compass: the European way for the Digital Decade | B3: European Commission | C3: https://eur-lex.europa.eu/legal-content/en/TXT/?uri=CELEX%3A52021DC0118 | G3: international | H3: 09/03/2021 | I3: International organisation | M3: =IF(ISNUMBER(SEARCH(",",I3)),"multistakeholders",lower(I3)) -> international organisation | N3: =IF(LOWER(I3)=LOWER(Maria!L3),1,0) -> 1 | O3: =IF(LOWER(I3)=LOWER(Aina!N3),1,0) -> 1 | P3: =IF(LOWER(I3)=LOWER(Kappa!Y5),1,0) -> 1 | R3: =T3/$T$9 -> 0.18181818 | S3: academia | T3: 8 | U3: 4 | V3: 4 | W3: 4 | X3: =U3/$T3 -> 0.5 | Y3: =V3/$T3 -> 0.5 | Z3: =W3/$T3 -> 0.5
A4: Global competition and convergence of AI Law | B4: Vrije Universiteit Brussel | C4: https://osf.io/preprints/socarxiv/j36ke/ | G4: Belgium | H4: 2021 | I4: Academia | M4: =IF(ISNUMBER(SEARCH(",",I4)),"multistakeholders",lower(I4)) -> academia | N4: =IF(LOWER(I4)=LOWER(Maria!L4),1,0) -> 1 | O4: =IF(LOWER(I4)=LOWER(Aina!N4),1,0) -> 1 | P4: =IF(LOWER(I4)=LOWER(Kappa!Y6),1,0) -> 1 | R4: =T4/$T$9 -> 0.15909091 | S4: civil society | T4: 7 | U4: 5 | V4: 7 | W4: 6 | X4: =U4/$T4 -> 0.71428571 | Y4: =V4/$T4 -> 1 | Z4: =W4/$T4 -> 0.85714286
A5: Technology rules? The advent of new technologies in the justice system | B5: House of Lords, Justice and Home affairs Committee (United Kingdom) | C5: https://publications.parliament.uk/pa/ld5802/ldselect/ldjusthom/180/180.pdf | G5: UK | H5: 30/03/2022 | I5: National authority | M5: =IF(ISNUMBER(SEARCH(",",I5)),"multistakeholders",lower(I5)) -> national authority | N5: =IF(LOWER(I5)=LOWER(Maria!L5),1,0) -> 1 | O5: =IF(LOWER(I5)=LOWER(Aina!N5),1,0) -> 1 | P5: =IF(LOWER(I5)=LOWER(Kappa!Y7),1,0) -> 1 | R5: =T5/$T$9 -> 0.22727273 | S5: international organisation | T5: 10 | U5: 8 | V5: 9 | W5: 10 | X5: =U5/$T5 -> 0.8 | Y5: =V5/$T5 -> 0.9 | Z5: =W5/$T5 -> 1
A6: Algorithmic discrimination in Europe: Challenges and opportunities for gender equality and non-discrimination law | B6: European Commission (European network of legal experts in gender equality and non-discrimination) | C6: https://op.europa.eu/en/publication-detail/-/publication/082f1dbc-821d-11eb-9ac9-01aa75ed71a1 | G6: EU | H6: 10/2020 | I6: International organisation | M6: =IF(ISNUMBER(SEARCH(",",I6)),"multistakeholders",lower(I6)) -> international organisation | N6: =IF(LOWER(I6)=LOWER(Maria!L6),1,0) -> 1 | O6: =IF(LOWER(I6)=LOWER(Aina!N6),1,0) -> 1 | P6: =IF(LOWER(I6)=LOWER(Kappa!Y8),1,0) -> 1 | R6: =T6/$T$9 -> 0.13636364 | S6: multistakeholders | T6: 6 | U6: 0 | V6: 0 | W6: 0 | X6: =U6/$T6 -> 0 | Y6: =V6/$T6 -> 0 | Z6: =W6/$T6 -> 0
A7: AI Index 2019 | B7: University of Stanford, SRI International, MIT, OpenAI, McKinsey Global Institute, Partnership on AI, Harvard University | C7: https://hai.stanford.edu/sites/default/files/ai_index_2019_report.pdf | G7: USA | H7: 2019 | I7: Academia | M7: =IF(ISNUMBER(SEARCH(",",I7)),"multistakeholders",lower(I7)) -> academia | N7: =IF(LOWER(I7)=LOWER(Maria!L7),1,0) -> 0 | O7: =IF(LOWER(I7)=LOWER(Aina!N7),1,0) -> 0 | P7: =IF(LOWER(I7)=LOWER(Kappa!Y9),1,0) -> 0 | R7: =T7/$T$9 -> 0.18181818 | S7: national authority | T7: 8 | U7: 4 | V7: 6 | W7: 8 | X7: =U7/$T7 -> 0.5 | Y7: =V7/$T7 -> 0.75 | Z7: =W7/$T7 -> 1
A8: Artificial intelligence and the control of COVID-19 | B8: Council of Europe | C8: https://www.coe.int/en/web/artificial-intelligence/ai-and-control-of-covid-19-coronavirus | G8: EU | H8: 2020 | I8: International organisation | M8: =IF(ISNUMBER(SEARCH(",",I8)),"multistakeholders",lower(I8)) -> international organisation | N8: =IF(LOWER(I8)=LOWER(Maria!L8),1,0) -> 1 | O8: =IF(LOWER(I8)=LOWER(Aina!N8),1,0) -> 1 | P8: =IF(LOWER(I8)=LOWER(Kappa!Y10),1,0) -> 1 | R8: =T8/$T$9 -> 0.11363636 | S8: private sector | T8: 5 | U8: 2 | V8: 2 | W8: 2 | X8: =U8/$T8 -> 0.4 | Y8: =V8/$T8 -> 0.4 | Z8: =W8/$T8 -> 0.4
A9: Unified Ethical Frame for Big Data Analysis. IAF Big Data Ethics Initiative, Part A | B9: The Information Accountability Foundation | C9: https://bigdata.fpf.org/wp-content/uploads/2015/11/IAF-Unified-Ethical-Frame-for-Big-Data-Analysis.pdf | G9: UK | H9: 03/2015 | I9: Private sector, Civil society | K9: (Funded by the The Information Accountability Foundation, which is a non profit think tank financed by american compagnies) | M9: =IF(ISNUMBER(SEARCH(",",I9)),"multistakeholders",lower(I9)) -> multistakeholders | N9: =IF(LOWER(I9)=LOWER(Maria!L9),1,0) -> 0 | O9: =IF(LOWER(I9)=LOWER(Aina!N9),1,0) -> 0 | P9: =IF(LOWER(I9)=LOWER(Kappa!Y11),1,0) -> 0 | S9: Total général | T9: 44 | U9: 23 | V9: 28 | W9: 30 | X9: =U9/$T9 -> 0.52272727 | Y9: =V9/$T9 -> 0.63636364 | Z9: =W9/$T9 -> 0.68181818
A10: Artificial Intelligence | B10: Samsung Research | C10: https://research.samsung.com/artificial-intelligence | G10: South Korea | I10: Private sector | M10: =IF(ISNUMBER(SEARCH(",",I10)),"multistakeholders",lower(I10)) -> private sector | N10: =IF(LOWER(I10)=LOWER(Maria!L10),1,0) -> 1 | O10: =IF(LOWER(I10)=LOWER(Aina!N10),1,0) -> 1 | P10: =IF(LOWER(I10)=LOWER(Kappa!Y12),1,0) -> 1
A11: The EURON Roboethics Roadmap | B11: The European Robotics Research Network (EURON) | C11: http://www.roboethics.org/index_file/Roboethics%20Roadmap%20Rel.1.2.pdf | G11: EU | H11: 01/2007 | I11: Academia, International organisation | K11: (Fondé/interlocuteur de la commision européenne) | M11: =IF(ISNUMBER(SEARCH(",",I11)),"multistakeholders",lower(I11)) -> multistakeholders | N11: =IF(LOWER(I11)=LOWER(Maria!L11),1,0) -> 0 | O11: =IF(LOWER(I11)=LOWER(Aina!N11),1,0) -> 0 | P11: =IF(LOWER(I11)=LOWER(Kappa!Y13),1,0) -> 0
A12: Understanding Artificial Intelligence and Safety - A guide for the responsible design and implementation of AI systems in the public sector | B12: The Alan Turing Institute | C12: https://www.turing.ac.uk/sites/default/files/2019-06/understanding_artificial_intelligence_ethics_and_safety.pdf | G12: UK | H12: 2019 | I12: Academia | K12: (Only universities, funded by grants/universities) | M12: =IF(ISNUMBER(SEARCH(",",I12)),"multistakeholders",lower(I12)) -> academia | N12: =IF(LOWER(I12)=LOWER(Maria!L12),1,0) -> 0 | O12: =IF(LOWER(I12)=LOWER(Aina!N12),1,0) -> 1 | P12: =IF(LOWER(I12)=LOWER(Kappa!Y14),1,0) -> 0
A13: Digital Ethics: A guide for professionals of the Digital Age | B13: CIGREF/Syntec Numérique | C13: https://www.cigref.fr/wp/wp-content/uploads/2019/02/Cigref-Syntec-Digital-Ethics-Guide-for-Professionals-of-Digital-Age-2018-October-EN.pdf | G13: France | H13: 10/2018 | I13: Private sector | M13: =IF(ISNUMBER(SEARCH(",",I13)),"multistakeholders",lower(I13)) -> private sector | N13: =IF(LOWER(I13)=LOWER(Maria!L13),1,0) -> 0 | O13: =IF(LOWER(I13)=LOWER(Aina!N13),1,0) -> 0 | P13: =IF(LOWER(I13)=LOWER(Kappa!Y15),1,0) -> 0
A14: Human Rights, Democracy, and the Rule of Law Assurance Framework for AI Systems: A proposal prepared for the Council of Europe’s Ad hoc Committee on Artificial Intelligence | B14: The Alan Turing Institute | C14: https://rm.coe.int/huderaf-coe-final-1-2752-6741-5300-v-1/1680a3f688 | G14: UK | H14: 2021 | I14: Academia | M14: =IF(ISNUMBER(SEARCH(",",I14)),"multistakeholders",lower(I14)) -> academia | N14: =IF(LOWER(I14)=LOWER(Maria!L14),1,0) -> 0 | O14: =IF(LOWER(I14)=LOWER(Aina!N14),1,0) -> 0 | P14: =IF(LOWER(I14)=LOWER(Kappa!Y16),1,0) -> 0
A15: Study on AI Governance by Human Rights-Centred Design, Deliberation and Oversight | B15: University of Birmingham | C15: https://papers.ssrn.com/sol3/papers.cfm?abstract_id=3435011 | G15: UK | H15: 09/08/2019 | I15: Academia | M15: =IF(ISNUMBER(SEARCH(",",I15)),"multistakeholders",lower(I15)) -> academia | N15: =IF(LOWER(I15)=LOWER(Maria!L15),1,0) -> 1 | O15: =IF(LOWER(I15)=LOWER(Aina!N15),1,0) -> 1 | P15: =IF(LOWER(I15)=LOWER(Kappa!Y17),1,0) -> 1
A16: European ethical Charter on the use of Artificial Intelligence in judicial systems and their environment | B16: Council of Europe: European Commission for the efficiency of Justice (CEPEJ) | C16: https://rm.coe.int/ethical-charter-en-for-publication-4-december-2018/16808f699c | G16: EU | H16: 04/12/2018 | I16: International organisation | M16: =IF(ISNUMBER(SEARCH(",",I16)),"multistakeholders",lower(I16)) -> international organisation | N16: =IF(LOWER(I16)=LOWER(Maria!L16),1,0) -> 1 | O16: =IF(LOWER(I16)=LOWER(Aina!N16),1,0) -> 1 | P16: =IF(LOWER(I16)=LOWER(Kappa!Y18),1,0) -> 1
A17: The Road to a Human-Centred Digital Society | B17: Centre on AI Technology for Humanking (AiTH) at NUS Business School | C17: https://drive.google.com/uc?export=download&id=1aRyqczni56ONA9PVExt2DrrJ1ATGKSu0 | D17: David De Cremer, Devesh Narayanan, Andreas Deppeler, Mahak Nagpal, Jack McGuire, Jess Zhang | E17: National University of Singapore | G17: Singapore | H17: 12/2021 | I17: Academia | M17: =IF(ISNUMBER(SEARCH(",",I17)),"multistakeholders",lower(I17)) -> academia | N17: =IF(LOWER(I17)=LOWER(Maria!L17),1,0) -> 1 | O17: =IF(LOWER(I17)=LOWER(Aina!N17),1,0) -> 1 | P17: =IF(LOWER(I17)=LOWER(Kappa!Y19),1,0) -> 1
A18: AI Roadmap | B18: AI Council (United Kingdom) | C18: https://assets.publishing.service.gov.uk/media/5ff3bc6e8fa8f53b76ccee23/AI_Council_AI_Roadmap.pdf | G18: UK | H18: 01/2021 | I18: Civil society | M18: =IF(ISNUMBER(SEARCH(",",I18)),"multistakeholders",lower(I18)) -> civil society | N18: =IF(LOWER(I18)=LOWER(Maria!L18),1,0) -> 0 | O18: =IF(LOWER(I18)=LOWER(Aina!N18),1,0) -> 1 | P18: =IF(LOWER(I18)=LOWER(Kappa!Y20),1,0) -> 0
A19: Growing the artificial intelligence industry in the UK | B19: Department for Digital, Culture, Media & Sport and Department for Business, Energy & Industrial Strategy (United Kingdom) | C19: https://www.gov.uk/government/publications/growing-the-artificial-intelligence-industry-in-the-uk | G19: UK | H19: 15/10/2017 | I19: National authority | M19: =IF(ISNUMBER(SEARCH(",",I19)),"multistakeholders",lower(I19)) -> national authority | N19: =IF(LOWER(I19)=LOWER(Maria!L19),1,0) -> 0 | O19: =IF(LOWER(I19)=LOWER(Aina!N19),1,0) -> 0 | P19: =IF(LOWER(I19)=LOWER(Kappa!Y21),1,0) -> 1
A20: AI Now 2017 Report | B20: AI Now Institute | C20: https://ainowinstitute.org/wp-content/uploads/2023/04/AI_Now_2017_Report.pdf | G20: USA | H20: 2017 | I20: Academia, Civil society | K20: (?) | M20: =IF(ISNUMBER(SEARCH(",",I20)),"multistakeholders",lower(I20)) -> multistakeholders | N20: =IF(LOWER(I20)=LOWER(Maria!L20),1,0) -> 0 | O20: =IF(LOWER(I20)=LOWER(Aina!N20),1,0) -> 0 | P20: =IF(LOWER(I20)=LOWER(Kappa!Y22),1,0) -> 0
A21: Algorithms in Decision Making | B21: Parliament Science and Technology Committee (United Kingdom) | C21: https://publications.parliament.uk/pa/cm201719/cmselect/cmsctech/351/351.pdf | G21: UK | H21: 23/05/2018 | I21: National authority | M21: =IF(ISNUMBER(SEARCH(",",I21)),"multistakeholders",lower(I21)) -> national authority | N21: =IF(LOWER(I21)=LOWER(Maria!L21),1,0) -> 0 | O21: =IF(LOWER(I21)=LOWER(Aina!N21),1,0) -> 1 | P21: =IF(LOWER(I21)=LOWER(Kappa!Y23),1,0) -> 1
A22: Thematic Reviews on 'Social Aspects of Digitalisation' (SPC) and 'Digitalisation and Robotisation of Work' (EMCO) - Endorsement of the joint key messages, 14411/18 | B22: Council of the European Union | C22: http://data.consilium.europa.eu/doc/document/ST-14411-2018-INIT/en/pdf | G22: EU | H22: 19/11/2018 | I22: International organisation | M22: =IF(ISNUMBER(SEARCH(",",I22)),"multistakeholders",lower(I22)) -> international organisation | N22: =IF(LOWER(I22)=LOWER(Maria!L22),1,0) -> 1 | O22: =IF(LOWER(I22)=LOWER(Aina!N22),1,0) -> 1 | P22: =IF(LOWER(I22)=LOWER(Kappa!Y24),1,0) -> 1
A23: Standards for AI Governance: International Standards to Enable Global Coordination in AI Research & Development | B23: Future of Humanity Institute, University of Oxford | C23: https://www.fhi.ox.ac.uk/wp-content/uploads/Standards_-FHI-Technical-Report.pdf | G23: international | H23: 04/2019 | I23: Academia | M23: =IF(ISNUMBER(SEARCH(",",I23)),"multistakeholders",lower(I23)) -> academia | N23: =IF(LOWER(I23)=LOWER(Maria!L23),1,0) -> 0 | O23: =IF(LOWER(I23)=LOWER(Aina!N23),1,0) -> 0 | P23: =IF(LOWER(I23)=LOWER(Kappa!Y25),1,0) -> 1
A24: Preparing the future of AI | B24: National Science and Technology Council (US) | C24: https://obamawhitehouse.archives.gov/sites/default/files/whitehouse_files/microsites/ostp/NSTC/preparing_for_the_future_of_ai.pdf | G24: USA | H24: 10/2016 | I24: National authority | M24: =IF(ISNUMBER(SEARCH(",",I24)),"multistakeholders",lower(I24)) -> national authority | N24: =IF(LOWER(I24)=LOWER(Maria!L24),1,0) -> 1 | O24: =IF(LOWER(I24)=LOWER(Aina!N24),1,0) -> 1 | P24: =IF(LOWER(I24)=LOWER(Kappa!Y26),1,0) -> 1
A25: AI Now Report 2016. The Social and Economic Implications of Artificial Intelligence Technologies in the Near-Term | B25: AI Now Institute | C25: https://assets.ctfassets.net/8wprhhvnpfc0/3JOy5k4f1YSCQOi8MCCmA2/97010d04fbc7892662ce8b2469dc1601/AI_Now_2016_Report.pdf | G25: USA | H25: 22/09/2016 | I25: Academia, Civil society | M25: =IF(ISNUMBER(SEARCH(",",I25)),"multistakeholders",lower(I25)) -> multistakeholders | N25: =IF(LOWER(I25)=LOWER(Maria!L25),1,0) -> 0 | O25: =IF(LOWER(I25)=LOWER(Aina!N25),1,0) -> 0 | P25: =IF(LOWER(I25)=LOWER(Kappa!Y27),1,0) -> 0
A26: G20 AI Principles | B26: Ministry of Internal Affairs and Communications | C26: https://www.mofa.go.jp/policy/economy/g20_summit/osaka19/pdf/documents/en/annex_08.pdf | G26: Japan | H26: 2019 | I26: National authority | M26: =IF(ISNUMBER(SEARCH(",",I26)),"multistakeholders",lower(I26)) -> national authority | N26: =IF(LOWER(I26)=LOWER(Maria!L26),1,0) -> 0 | O26: =IF(LOWER(I26)=LOWER(Aina!N26),1,0) -> 0 | P26: =IF(LOWER(I26)=LOWER(Kappa!Y28),1,0) -> 1
A27: Principles for the Governance of AI | B27: The Future Society Science Law and Society (SLS) Initiative | C27: https://thefuturesociety.org/principles-law-and-society-initiative/ | G27: USA | H27: 15/07/2017 | I27: Civil society | M27: =IF(ISNUMBER(SEARCH(",",I27)),"multistakeholders",lower(I27)) -> civil society | N27: =IF(LOWER(I27)=LOWER(Maria!L27),1,0) -> 1 | O27: =IF(LOWER(I27)=LOWER(Aina!N27),1,0) -> 1 | P27: =IF(LOWER(I27)=LOWER(Kappa!Y29),1,0) -> 1
A28: 4 Steps to developing Responsible AI | B28: World Economic Forum (WEF) | C28: https://www.weforum.org/agenda/2019/06/4-steps-to-developing-responsible-ai/ | G28: international | H28: 20/06/2019 | I28: Private sector | M28: =IF(ISNUMBER(SEARCH(",",I28)),"multistakeholders",lower(I28)) -> private sector | N28: =IF(LOWER(I28)=LOWER(Maria!L28),1,0) -> 0 | O28: =IF(LOWER(I28)=LOWER(Aina!N28),1,0) -> 0 | P28: =IF(LOWER(I28)=LOWER(Kappa!Y30),1,0) -> 0
A29: Opinion on AI - The consequences of artificial intelligence on the (digital) single market, production, consumption, employment and society’ | B29: European Economic and Social Committee (EESC) | C29: https://eur-lex.europa.eu/legal-content/EN/TXT/PDF/?uri=CELEX:52016IE5369&from=EN | G29: international | H29: 31/08/2017 | I29: International organisation | M29: =IF(ISNUMBER(SEARCH(",",I29)),"multistakeholders",lower(I29)) -> international organisation | N29: =IF(LOWER(I29)=LOWER(Maria!L29),1,0) -> 0 | O29: =IF(LOWER(I29)=LOWER(Aina!N29),1,0) -> 1 | P29: =IF(LOWER(I29)=LOWER(Kappa!Y31),1,0) -> 1
A30: Human Rights Impact Assessments for AI: Analysis and Recommendations | B30: AccessNow | C30: https://www.accessnow.org/cms/assets/uploads/2022/11/Access-Now-Version-Human-Rights-Implications-of-Algorithmic-Impact-Assessments_-Priority-Recommendations-to-Guide-Effective-Development-and-Use.pdf | G30: USA | H30: 10/2022 | I30: Academia, Civil society | M30: =IF(ISNUMBER(SEARCH(",",I30)),"multistakeholders",lower(I30)) -> multistakeholders | N30: =IF(LOWER(I30)=LOWER(Maria!L30),1,0) -> 0 | O30: =IF(LOWER(I30)=LOWER(Aina!N30),1,0) -> 0 | P30: =IF(LOWER(I30)=LOWER(Kappa!Y32),1,0) -> 0
A31: Report on Artificial intelligence in health care: medical, legal and ethical challenges ahead | B31: Council of Europe (Parliamentary Assembly) | C31: https://pace.coe.int/files/28737/pdf | G31: EU | H31: 01/10/2020 | I31: International organisation | M31: =IF(ISNUMBER(SEARCH(",",I31)),"multistakeholders",lower(I31)) -> international organisation | N31: =IF(LOWER(I31)=LOWER(Maria!L31),1,0) -> 1 | O31: =IF(LOWER(I31)=LOWER(Aina!N31),1,0) -> 1 | P31: =IF(LOWER(I31)=LOWER(Kappa!Y33),1,0) -> 1
A32: Recomendations on the inclusion subSaharan Africa in Global AI Ethics | B32: Research ICT Africa | C32: https://researchictafrica.net/ranitp2019-2-ai-ethics/ | G32: South Africa | H32: 02/2019 | I32: Civil society, Academia | M32: =IF(ISNUMBER(SEARCH(",",I32)),"multistakeholders",lower(I32)) -> multistakeholders | N32: =IF(LOWER(I32)=LOWER(Maria!L32),1,0) -> 0 | O32: =IF(LOWER(I32)=LOWER(Aina!N32),1,0) -> 0 | P32: =IF(LOWER(I32)=LOWER(Kappa!Y34),1,0) -> 0
A33: Our principles | B33: Google | C33: https://blog.google/technology/ai/ai-principles/ | D33: . | E33: . | G33: USA | H33: 2018 | I33: Private sector | M33: =IF(ISNUMBER(SEARCH(",",I33)),"multistakeholders",lower(I33)) -> private sector | N33: =IF(LOWER(I33)=LOWER(Maria!L33),1,0) -> 1 | O33: =IF(LOWER(I33)=LOWER(Aina!N33),1,0) -> 1 | P33: =IF(LOWER(I33)=LOWER(Kappa!Y35),1,0) -> 1
A34: Unfairness by algorithm: Distilling the Harms of automated decision making | B34: Future of Privacy Forum | C34: https://fpf.org/wp-content/uploads/2017/12/FPF-Automated-Decision-Making-Harms-and-Mitigation-Charts.pdf | G34: USA | H34: 12/2017 | I34: Civil society | M34: =IF(ISNUMBER(SEARCH(",",I34)),"multistakeholders",lower(I34)) -> civil society | N34: =IF(LOWER(I34)=LOWER(Maria!L34),1,0) -> 1 | O34: =IF(LOWER(I34)=LOWER(Aina!N34),1,0) -> 1 | P34: =IF(LOWER(I34)=LOWER(Kappa!Y36),1,0) -> 1
A35: Automated Decision-Making Under the GDPR: Practical Cases from Courts and Data Protection Authorities | B35: Future of Privacy Forum | C35: https://fpf.org/wp-content/uploads/2022/05/FPF-ADM-Report-R2-singles.pdf | G35: USA | H35: 05/2022 | I35: Civil society | M35: =IF(ISNUMBER(SEARCH(",",I35)),"multistakeholders",lower(I35)) -> civil society | N35: =IF(LOWER(I35)=LOWER(Maria!L35),1,0) -> 1 | O35: =IF(LOWER(I35)=LOWER(Aina!N35),1,0) -> 1 | P35: =IF(LOWER(I35)=LOWER(Kappa!Y37),1,0) -> 1
A36: Big Data and AI Principles in Engineering | B36: World Federation of Engineering Organizations (WEFO) | C36: http://www.wfeo.org/big-data-and-ai-principles-in-engineering/ | G36: France | H36: 2020 | I36: Private sector | M36: =IF(ISNUMBER(SEARCH(",",I36)),"multistakeholders",lower(I36)) -> private sector | N36: =IF(LOWER(I36)=LOWER(Maria!L36),1,0) -> 0 | O36: =IF(LOWER(I36)=LOWER(Aina!N36),1,0) -> 0 | P36: =IF(LOWER(I36)=LOWER(Kappa!Y38),1,0) -> 0
A37: RFI for AI Services | B37: TBS Canada | C37: https://buyandsell.gc.ca/cds/public/2018/06/28/05baa93c08b6f2d3000855170f831066/ABES.PROD.PW__EE.B017.E33657.EBSU000.PDF | G37: Canada | H37: 28/06/2018 | I37: National authority | K37: Pas trouvé le document | M37: =IF(ISNUMBER(SEARCH(",",I37)),"multistakeholders",lower(I37)) -> national authority | N37: =IF(LOWER(I37)=LOWER(Maria!L37),1,0) -> 1 | O37: =IF(LOWER(I37)=LOWER(Aina!N37),1,0) -> 1 | P37: =IF(LOWER(I37)=LOWER(Kappa!Y39),1,0) -> 1
A38: Beyond pilots: sustainable implementation of AI in public services | B38: European Commission (Joint Research Centre, AI Watch) | C38: https://publications.jrc.ec.europa.eu/repository/bitstream/JRC126665/jrc126665_sustainable_implementation_of_ai_in_public_services_technical-report_v2.pdf | G38: EU | H38: 2021 | I38: International organisation | M38: =IF(ISNUMBER(SEARCH(",",I38)),"multistakeholders",lower(I38)) -> international organisation | N38: =IF(LOWER(I38)=LOWER(Maria!L38),1,0) -> 0 | O38: =IF(LOWER(I38)=LOWER(Aina!N38),1,0) -> 0 | P38: =IF(LOWER(I38)=LOWER(Kappa!Y40),1,0) -> 1
A39: Open letter: Civil society call for the introduction of red lines in the upcoming European Commission proposal on Artificial Intelligence | B39: European Digital Rights (EDRi) | C39: https://edri.org/wp-content/uploads/2021/01/EDRi-open-letter-AI-red-lines.pdf | G39: Belgium | H39: 12/01/2021 | I39: Civil Society | M39: =IF(ISNUMBER(SEARCH(",",I39)),"multistakeholders",lower(I39)) -> civil society | N39: =IF(LOWER(I39)=LOWER(Maria!L39),1,0) -> 0 | O39: =IF(LOWER(I39)=LOWER(Aina!N39),1,0) -> 1 | P39: =IF(LOWER(I39)=LOWER(Kappa!Y41),1,0) -> 1
A40: Governance Principles for a New Generation of Artificial Intelligence: Develop Responsible Artificial Intelligence | B40: National New Generation Artificial Intelligence Governance Expert Committee | C40: https://www.newamerica.org/cybersecurity-initiative/digichina/blog/translation-chinese-expert-group-offers-governance-principles-responsible-ai/ | G40: China | H40: 2019 | I40: National authority | M40: =IF(ISNUMBER(SEARCH(",",I40)),"multistakeholders",lower(I40)) -> national authority | N40: =IF(LOWER(I40)=LOWER(Maria!L40),1,0) -> 0 | O40: =IF(LOWER(I40)=LOWER(Aina!N40),1,0) -> 1 | P40: =IF(LOWER(I40)=LOWER(Kappa!Y42),1,0) -> 1
...

Sheet Maria
A1: Title | B1: Institution | C1: URL | G1: Country | H1: Date | I1: Sector | M1: Matthieu | N1: Aina | O1: Simon
A2: AI Index 2022 | B2: University of Stanford, SRI International, MIT, OpenAI, McKinsey Global Institute, Partnership on AI, Harvard University | C2: https://aiindex.stanford.edu/wp-content/uploads/2022/03/2022-AI-Index-Report_Master.pdf | G2: USA | H2: 2022 | I2: academia | L2: =IF(ISNUMBER(SEARCH(",",I2)),"multistakeholders",lower(I2)) -> academia | M2: =IF(LOWER(L2)=LOWER(Matthieu!M2),1,0) -> 1 | N2: =IF(LOWER(L2)=LOWER(Aina!N2),1,0) -> 0 | O2: =IF(LOWER(L2)=LOWER(Kappa!Y4),1,0) -> 0 | P2: Maria | R2: COUNTA de | S2: SUM de Matthieu | T2: SUM de Aina | U2: SUM de Simon | V2: Matthieu | W2: Aina | X2: Simon
A3: 2030 Digital Compass: the European way for the Digital Decade | B3: European Commission | C3: https://eur-lex.europa.eu/legal-content/en/TXT/?uri=CELEX%3A52021DC0118 | G3: international | H3: 09/03/2021 | I3: international organisation | L3: =IF(ISNUMBER(SEARCH(",",I3)),"multistakeholders",lower(I3)) -> international organisation | M3: =IF(LOWER(L3)=LOWER(Matthieu!M3),1,0) -> 1 | N3: =IF(LOWER(L3)=LOWER(Aina!N3),1,0) -> 1 | O3: =IF(LOWER(L3)=LOWER(Kappa!Y5),1,0) -> 1 | P3: =5/44 -> 0.11363636 | Q3: academia | R3: 5 | S3: 4 | T3: 4 | U3: 4 | V3: =S3/$R3 -> 0.8 | W3: =T3/$R3 -> 0.8 | X3: =U3/$R3 -> 0.8
A4: Global competition and convergence of AI Law | B4: Vrije Universiteit Brussel | C4: https://osf.io/preprints/socarxiv/j36ke/ | G4: Belgium | H4: 2021 | I4: academia | L4: =IF(ISNUMBER(SEARCH(",",I4)),"multistakeholders",lower(I4)) -> academia | M4: =IF(LOWER(L4)=LOWER(Matthieu!M4),1,0) -> 1 | N4: =IF(LOWER(L4)=LOWER(Aina!N4),1,0) -> 1 | O4: =IF(LOWER(L4)=LOWER(Kappa!Y6),1,0) -> 1 | P4: =6/44 -> 0.13636364 | Q4: civil society | R4: 6 | S4: 5 | T4: 6 | U4: 5 | V4: =S4/$R4 -> 0.83333333 | W4: =T4/$R4 -> 1 | X4: =U4/$R4 -> 0.83333333
A5: Technology rules? The advent of new technologies in the justice system | B5: House of Lords, Justice and Home affairs Committee (United Kingdom) | C5: https://publications.parliament.uk/pa/ld5802/ldselect/ldjusthom/180/180.pdf | G5: UK | H5: 30/03/2022 | I5: national authority | L5: =IF(ISNUMBER(SEARCH(",",I5)),"multistakeholders",lower(I5)) -> national authority | M5: =IF(LOWER(L5)=LOWER(Matthieu!M5),1,0) -> 1 | N5: =IF(LOWER(L5)=LOWER(Aina!N5),1,0) -> 1 | O5: =IF(LOWER(L5)=LOWER(Kappa!Y7),1,0) -> 1 | P5: =9/44 -> 0.20454545 | Q5: international organisation | R5: 9 | S5: 8 | T5: 9 | U5: 8 | V5: =S5/$R5 -> 0.88888889 | W5: =T5/$R5 -> 1 | X5: =U5/$R5 -> 0.88888889
A6: Algorithmic discrimination in Europe: Challenges and opportunities for gender equality and non-discrimination law | B6: European Commission (European network of legal experts in gender equality and non-discrimination) | C6: https://op.europa.eu/en/publication-detail/-/publication/082f1dbc-821d-11eb-9ac9-01aa75ed71a1 | G6: EU | H6: 10/2020 | I6: international organisation | L6: =IF(ISNUMBER(SEARCH(",",I6)),"multistakeholders",lower(I6)) -> international organisation | M6: =IF(LOWER(L6)=LOWER(Matthieu!M6),1,0) -> 1 | N6: =IF(LOWER(L6)=LOWER(Aina!N6),1,0) -> 1 | O6: =IF(LOWER(L6)=LOWER(Kappa!Y8),1,0) -> 1 | P6: =18/44 -> 0.40909091 | Q6: multistakeholders | R6: 18 | S6: 4 | T6: 8 | U6: 3 | V6: =S6/$R6 -> 0.22222222 | W6: =T6/$R6 -> 0.44444444 | X6: =U6/$R6 -> 0.16666667
A7: AI Index 2019 | B7: University of Stanford, SRI International, MIT, OpenAI, McKinsey Global Institute, Partnership on AI, Harvard University | C7: https://hai.stanford.edu/sites/default/files/ai_index_2019_report.pdf | G7: USA | H7: 2019 | I7: academia, private sector | L7: =IF(ISNUMBER(SEARCH(",",I7)),"multistakeholders",lower(I7)) -> multistakeholders | M7: =IF(LOWER(L7)=LOWER(Matthieu!M7),1,0) -> 0 | N7: =IF(LOWER(L7)=LOWER(Aina!N7),1,0) -> 1 | O7: =IF(LOWER(L7)=LOWER(Kappa!Y9),1,0) -> 1 | P7: =4/44 -> 0.090909091 | Q7: national authority | R7: 4 | S7: 4 | T7: 4 | U7: 4 | V7: =S7/$R7 -> 1 | W7: =T7/$R7 -> 1 | X7: =U7/$R7 -> 1
A8: Artificial intelligence and the control of COVID-19 | B8: Council of Europe | C8: https://www.coe.int/en/web/artificial-intelligence/ai-and-control-of-covid-19-coronavirus | G8: EU | H8: 2020 | I8: international organisation | L8: =IF(ISNUMBER(SEARCH(",",I8)),"multistakeholders",lower(I8)) -> international organisation | M8: =IF(LOWER(L8)=LOWER(Matthieu!M8),1,0) -> 1 | N8: =IF(LOWER(L8)=LOWER(Aina!N8),1,0) -> 1 | O8: =IF(LOWER(L8)=LOWER(Kappa!Y10),1,0) -> 1 | P8: =2/44 -> 0.045454545 | Q8: private sector | R8: 2 | S8: 2 | T8: 2 | U8: 2 | V8: =S8/$R8 -> 1 | W8: =T8/$R8 -> 1 | X8: =U8/$R8 -> 1
A9: Unified Ethical Frame for Big Data Analysis. IAF Big Data Ethics Initiative, Part A | B9: The Information Accountability Foundation | C9: https://bigdata.fpf.org/wp-content/uploads/2015/11/IAF-Unified-Ethical-Frame-for-Big-Data-Analysis.pdf | G9: UK | H9: 03/2015 | I9: civil society | L9: =IF(ISNUMBER(SEARCH(",",I9)),"multistakeholders",lower(I9)) -> civil society | M9: =IF(LOWER(L9)=LOWER(Matthieu!M9),1,0) -> 0 | N9: =IF(LOWER(L9)=LOWER(Aina!N9),1,0) -> 1 | O9: =IF(LOWER(L9)=LOWER(Kappa!Y11),1,0) -> 0 | Q9: Total général | R9: 44 | S9: 27 | T9: 33 | U9: 26 | V9: =S9/$R9 -> 0.61363636 | W9: =T9/$R9 -> 0.75 | X9: =U9/$R9 -> 0.59090909
A10: Artificial Intelligence | B10: Samsung Research | C10: https://research.samsung.com/artificial-intelligence | G10: South Korea | I10: private sector | L10: =IF(ISNUMBER(SEARCH(",",I10)),"multistakeholders",lower(I10)) -> private sector | M10: =IF(LOWER(L10)=LOWER(Matthieu!M10),1,0) -> 1 | N10: =IF(LOWER(L10)=LOWER(Aina!N10),1,0) -> 1 | O10: =IF(LOWER(L10)=LOWER(Kappa!Y12),1,0) -> 1
A11: The EURON Roboethics Roadmap | B11: The European Robotics Research Network (EURON) | C11: http://www.roboethics.org/index_file/Roboethics%20Roadmap%20Rel.1.2.pdf | G11: EU | H11: 01/2007 | I11: academia | L11: =IF(ISNUMBER(SEARCH(",",I11)),"multistakeholders",lower(I11)) -> academia | M11: =IF(LOWER(L11)=LOWER(Matthieu!M11),1,0) -> 0 | N11: =IF(LOWER(L11)=LOWER(Aina!N11),1,0) -> 1 | O11: =IF(LOWER(L11)=LOWER(Kappa!Y13),1,0) -> 1
A12: Understanding Artificial Intelligence and Safety - A guide for the responsible design and implementation of AI systems in the public sector | B12: The Alan Turing Institute | C12: https://www.turing.ac.uk/sites/default/files/2019-06/understanding_artificial_intelligence_ethics_and_safety.pdf | G12: UK | H12: 2019 | I12: academia, national authority | L12: =IF(ISNUMBER(SEARCH(",",I12)),"multistakeholders",lower(I12)) -> multistakeholders | M12: =IF(LOWER(L12)=LOWER(Matthieu!M12),1,0) -> 0 | N12: =IF(LOWER(L12)=LOWER(Aina!N12),1,0) -> 0 | O12: =IF(LOWER(L12)=LOWER(Kappa!Y14),1,0) -> 1
A13: Digital Ethics: A guide for professionals of the Digital Age | B13: CIGREF/Syntec Numérique | C13: https://www.cigref.fr/wp/wp-content/uploads/2019/02/Cigref-Syntec-Digital-Ethics-Guide-for-Professionals-of-Digital-Age-2018-October-EN.pdf | G13: France | H13: 10/2018 | I13: private sector, civil society | L13: =IF(ISNUMBER(SEARCH(",",I13)),"multistakeholders",lower(I13)) -> multistakeholders | M13: =IF(LOWER(L13)=LOWER(Matthieu!M13),1,0) -> 0 | N13: =IF(LOWER(L13)=LOWER(Aina!N13),1,0) -> 1 | O13: =IF(LOWER(L13)=LOWER(Kappa!Y15),1,0) -> 0
A14: Human Rights, Democracy, and the Rule of Law Assurance Framework for AI Systems: A proposal prepared for the Council of Europe’s Ad hoc Committee on Artificial Intelligence | B14: The Alan Turing Institute | C14: https://rm.coe.int/huderaf-coe-final-1-2752-6741-5300-v-1/1680a3f688 | G14: UK | H14: 2021 | I14: academia, national authority | L14: =IF(ISNUMBER(SEARCH(",",I14)),"multistakeholders",lower(I14)) -> multistakeholders | M14: =IF(LOWER(L14)=LOWER(Matthieu!M14),1,0) -> 0 | N14: =IF(LOWER(L14)=LOWER(Aina!N14),1,0) -> 1 | O14: =IF(LOWER(L14)=LOWER(Kappa!Y16),1,0) -> 1
A15: Study on AI Governance by Human Rights-Centred Design, Deliberation and Oversight | B15: University of Birmingham | C15: https://papers.ssrn.com/sol3/papers.cfm?abstract_id=3435011 | G15: UK | H15: 09/08/2019 | I15: academia | L15: =IF(ISNUMBER(SEARCH(",",I15)),"multistakeholders",lower(I15)) -> academia | M15: =IF(LOWER(L15)=LOWER(Matthieu!M15),1,0) -> 1 | N15: =IF(LOWER(L15)=LOWER(Aina!N15),1,0) -> 1 | O15: =IF(LOWER(L15)=LOWER(Kappa!Y17),1,0) -> 1
A16: European ethical Charter on the use of Artificial Intelligence in judicial systems and their environment | B16: Council of Europe: European Commission for the efficiency of Justice (CEPEJ) | C16: https://rm.coe.int/ethical-charter-en-for-publication-4-december-2018/16808f699c | G16: EU | H16: 04/12/2018 | I16: international organisation | L16: =IF(ISNUMBER(SEARCH(",",I16)),"multistakeholders",lower(I16)) -> international organisation | M16: =IF(LOWER(L16)=LOWER(Matthieu!M16),1,0) -> 1 | N16: =IF(LOWER(L16)=LOWER(Aina!N16),1,0) -> 1 | O16: =IF(LOWER(L16)=LOWER(Kappa!Y18),1,0) -> 1
A17: The Road to a Human-Centred Digital Society | B17: Centre on AI Technology for Humanking (AiTH) at NUS Business School | C17: https://drive.google.com/uc?export=download&id=1aRyqczni56ONA9PVExt2DrrJ1ATGKSu0 | D17: David De Cremer, Devesh Narayanan, Andreas Deppeler, Mahak Nagpal, Jack McGuire, Jess Zhang | E17: National University of Singapore | G17: Singapore | H17: 12/2021 | I17: academia | L17: =IF(ISNUMBER(SEARCH(",",I17)),"multistakeholders",lower(I17)) -> academia | M17: =IF(LOWER(L17)=LOWER(Matthieu!M17),1,0) -> 1 | N17: =IF(LOWER(L17)=LOWER(Aina!N17),1,0) -> 1 | O17: =IF(LOWER(L17)=LOWER(Kappa!Y19),1,0) -> 1
A18: AI Roadmap | B18: AI Council (United Kingdom) | C18: https://assets.publishing.service.gov.uk/media/5ff3bc6e8fa8f53b76ccee23/AI_Council_AI_Roadmap.pdf | G18: UK | H18: 01/2021 | I18: civil society, national authority | L18: =IF(ISNUMBER(SEARCH(",",I18)),"multistakeholders",lower(I18)) -> multistakeholders | M18: =IF(LOWER(L18)=LOWER(Matthieu!M18),1,0) -> 0 | N18: =IF(LOWER(L18)=LOWER(Aina!N18),1,0) -> 0 | O18: =IF(LOWER(L18)=LOWER(Kappa!Y20),1,0) -> 0
A19: Growing the artificial intelligence industry in the UK | B19: Department for Digital, Culture, Media & Sport and Department for Business, Energy & Industrial Strategy (United Kingdom) | C19: https://www.gov.uk/government/publications/growing-the-artificial-intelligence-industry-in-the-uk | G19: UK | H19: 15/10/2017 | I19: academia, private sector, national authority | L19: =IF(ISNUMBER(SEARCH(",",I19)),"multistakeholders",lower(I19)) -> multistakeholders | M19: =IF(LOWER(L19)=LOWER(Matthieu!M19),1,0) -> 0 | N19: =IF(LOWER(L19)=LOWER(Aina!N19),1,0) -> 1 | O19: =IF(LOWER(L19)=LOWER(Kappa!Y21),1,0) -> 0
A20: AI Now 2017 Report | B20: AI Now Institute | C20: https://ainowinstitute.org/wp-content/uploads/2023/04/AI_Now_2017_Report.pdf | G20: USA | H20: 2017 | I20: civil society, academia | L20: =IF(ISNUMBER(SEARCH(",",I20)),"multistakeholders",lower(I20)) -> multistakeholders | M20: =IF(LOWER(L20)=LOWER(Matthieu!M20),1,0) -> 1 | N20: =IF(LOWER(L20)=LOWER(Aina!N20),1,0) -> 0 | O20: =IF(LOWER(L20)=LOWER(Kappa!Y22),1,0) -> 0
A21: Algorithms in Decision Making | B21: Parliament Science and Technology Committee (United Kingdom) | C21: https://publications.parliament.uk/pa/cm201719/cmselect/cmsctech/351/351.pdf | G21: UK | H21: 23/05/2018 | I21: civil society, national authority | L21: =IF(ISNUMBER(SEARCH(",",I21)),"multistakeholders",lower(I21)) -> multistakeholders | M21: =IF(LOWER(L21)=LOWER(Matthieu!M21),1,0) -> 0 | N21: =IF(LOWER(L21)=LOWER(Aina!N21),1,0) -> 0 | O21: =IF(LOWER(L21)=LOWER(Kappa!Y23),1,0) -> 0
A22: Thematic Reviews on 'Social Aspects of Digitalisation' (SPC) and 'Digitalisation and Robotisation of Work' (EMCO) - Endorsement of the joint key messages, 14411/18 | B22: Council of the European Union | C22: http://data.consilium.europa.eu/doc/document/ST-14411-2018-INIT/en/pdf | G22: EU | H22: 19/11/2018 | I22: international organisation | L22: =IF(ISNUMBER(SEARCH(",",I22)),"multistakeholders",lower(I22)) -> international organisation | M22: =IF(LOWER(L22)=LOWER(Matthieu!M22),1,0) -> 1 | N22: =IF(LOWER(L22)=LOWER(Aina!N22),1,0) -> 1 | O22: =IF(LOWER(L22)=LOWER(Kappa!Y24),1,0) -> 1
A23: Standards for AI Governance: International Standards to Enable Global Coordination in AI Research & Development | B23: Future of Humanity Institute, University of Oxford | C23: https://www.fhi.ox.ac.uk/wp-content/uploads/Standards_-FHI-Technical-Report.pdf | G23: international | H23: 04/2019 | I23: civil society, academia | L23: =IF(ISNUMBER(SEARCH(",",I23)),"multistakeholders",lower(I23)) -> multistakeholders | M23: =IF(LOWER(L23)=LOWER(Matthieu!M23),1,0) -> 0 | N23: =IF(LOWER(L23)=LOWER(Aina!N23),1,0) -> 1 | O23: =IF(LOWER(L23)=LOWER(Kappa!Y25),1,0) -> 0
A24: Preparing the future of AI | B24: National Science and Technology Council (US) | C24: https://obamawhitehouse.archives.gov/sites/default/files/whitehouse_files/microsites/ostp/NSTC/preparing_for_the_future_of_ai.pdf | G24: USA | H24: 10/2016 | I24: national authority | L24: =IF(ISNUMBER(SEARCH(",",I24)),"multistakeholders",lower(I24)) -> national authority | M24: =IF(LOWER(L24)=LOWER(Matthieu!M24),1,0) -> 1 | N24: =IF(LOWER(L24)=LOWER(Aina!N24),1,0) -> 1 | O24: =IF(LOWER(L24)=LOWER(Kappa!Y26),1,0) -> 1
A25: AI Now Report 2016. The Social and Economic Implications of Artificial Intelligence Technologies in the Near-Term | B25: AI Now Institute | C25: https://assets.ctfassets.net/8wprhhvnpfc0/3JOy5k4f1YSCQOi8MCCmA2/97010d04fbc7892662ce8b2469dc1601/AI_Now_2016_Report.pdf | G25: USA | H25: 22/09/2016 | I25: national authority, academia | L25: =IF(ISNUMBER(SEARCH(",",I25)),"multistakeholders",lower(I25)) -> multistakeholders | M25: =IF(LOWER(L25)=LOWER(Matthieu!M25),1,0) -> 1 | N25: =IF(LOWER(L25)=LOWER(Aina!N25),1,0) -> 1 | O25: =IF(LOWER(L25)=LOWER(Kappa!Y27),1,0) -> 0
A26: G20 AI Principles | B26: Ministry of Internal Affairs and Communications | C26: https://www.mofa.go.jp/policy/economy/g20_summit/osaka19/pdf/documents/en/annex_08.pdf | G26: Japan | H26: 2019 | I26: international organisation | L26: =IF(ISNUMBER(SEARCH(",",I26)),"multistakeholders",lower(I26)) -> international organisation | M26: =IF(LOWER(L26)=LOWER(Matthieu!M26),1,0) -> 0 | N26: =IF(LOWER(L26)=LOWER(Aina!N26),1,0) -> 1 | O26: =IF(LOWER(L26)=LOWER(Kappa!Y28),1,0) -> 0
A27: Principles for the Governance of AI | B27: The Future Society Science Law and Society (SLS) Initiative | C27: https://thefuturesociety.org/principles-law-and-society-initiative/ | G27: USA | H27: 15/07/2017 | I27: civil society | L27: =IF(ISNUMBER(SEARCH(",",I27)),"multistakeholders",lower(I27)) -> civil society | M27: =IF(LOWER(L27)=LOWER(Matthieu!M27),1,0) -> 1 | N27: =IF(LOWER(L27)=LOWER(Aina!N27),1,0) -> 1 | O27: =IF(LOWER(L27)=LOWER(Kappa!Y29),1,0) -> 1
A28: 4 Steps to developing Responsible AI | B28: World Economic Forum (WEF) | C28: https://www.weforum.org/agenda/2019/06/4-steps-to-developing-responsible-ai/ | G28: international | H28: 20/06/2019 | I28: civil society, international organisation | L28: =IF(ISNUMBER(SEARCH(",",I28)),"multistakeholders",lower(I28)) -> multistakeholders | M28: =IF(LOWER(L28)=LOWER(Matthieu!M28),1,0) -> 0 | N28: =IF(LOWER(L28)=LOWER(Aina!N28),1,0) -> 0 | O28: =IF(LOWER(L28)=LOWER(Kappa!Y30),1,0) -> 0
A29: Opinion on AI - The consequences of artificial intelligence on the (digital) single market, production, consumption, employment and society’ | B29: European Economic and Social Committee (EESC) | C29: https://eur-lex.europa.eu/legal-content/EN/TXT/PDF/?uri=CELEX:52016IE5369&from=EN | G29: international | H29: 31/08/2017 | I29: international organisation, civil society | L29: =IF(ISNUMBER(SEARCH(",",I29)),"multistakeholders",lower(I29)) -> multistakeholders | M29: =IF(LOWER(L29)=LOWER(Matthieu!M29),1,0) -> 0 | N29: =IF(LOWER(L29)=LOWER(Aina!N29),1,0) -> 0 | O29: =IF(LOWER(L29)=LOWER(Kappa!Y31),1,0) -> 0
... A32: Recomendations on the inclusion subSaharan Africa in Global AI Ethics | B32: Research ICT Africa | C32: https://researchictafrica.net/ranitp2019-2-ai-ethics/ | G32: South Africa | H32: 02/2019 | I32: academia, civil society | L32: =IF(ISNUMBER(SEARCH(",",I32)),"multistakeholders",lower(I32)) -> multistakeholders | M32: =IF(LOWER(L32)=LOWER(Matthieu!M32),1,0) -> 1 | N32: =IF(LOWER(L32)=LOWER(Aina!N32),1,0) -> 0 | O32: =IF(LOWER(L32)=LOWER(Kappa!Y34),1,0) -> 0
A33: Our principles | B33: Google | C33: https://blog.google/technology/ai/ai-principles/ | D33: . | E33: . | G33: USA | H33: 2018 | I33: private sector | L33: =IF(ISNUMBER(SEARCH(",",I33)),"multistakeholders",lower(I33)) -> private sector | M33: =IF(LOWER(L33)=LOWER(Matthieu!M33),1,0) -> 1 | N33: =IF(LOWER(L33)=LOWER(Aina!N33),1,0) -> 1 | O33: =IF(LOWER(L33)=LOWER(Kappa!Y35),1,0) -> 1
A34: Unfairness by algorithm: Distilling the Harms of automated decision making | B34: Future of Privacy Forum | C34: https://fpf.org/wp-content/uploads/2017/12/FPF-Automated-Decision-Making-Harms-and-Mitigation-Charts.pdf | G34: USA | H34: 12/2017 | I34: civil society | L34: =IF(ISNUMBER(SEARCH(",",I34)),"multistakeholders",lower(I34)) -> civil society | M34: =IF(LOWER(L34)=LOWER(Matthieu!M34),1,0) -> 1 | N34: =IF(LOWER(L34)=LOWER(Aina!N34),1,0) -> 1 | O34: =IF(LOWER(L34)=LOWER(Kappa!Y36),1,0) -> 1
A35: Automated Decision-Making Under the GDPR: Practical Cases from Courts and Data Protection Authorities | B35: Future of Privacy Forum | C35: https://fpf.org/wp-content/uploads/2022/05/FPF-ADM-Report-R2-singles.pdf | G35: USA | H35: 05/2022 | I35: civil society | L35: =IF(ISNUMBER(SEARCH(",",I35)),"multistakeholders",lower(I35)) -> civil society | M35: =IF(LOWER(L35)=LOWER(Matthieu!M35),1,0) -> 1 | N35: =IF(LOWER(L35)=LOWER(Aina!N35),1,0) -> 1 | O35: =IF(LOWER(L35)=LOWER(Kappa!Y37),1,0) -> 1
A36: Big Data and AI Principles in Engineering | B36: World Federation of Engineering Organizations (WEFO) | C36: http://www.wfeo.org/big-data-and-ai-principles-in-engineering/ | G36: France | H36: 2020 | I36: civil society, private sector | L36: =IF(ISNUMBER(SEARCH(",",I36)),"multistakeholders",lower(I36)) -> multistakeholders | M36: =IF(LOWER(L36)=LOWER(Matthieu!M36),1,0) -> 0 | N36: =IF(LOWER(L36)=LOWER(Aina!N36),1,0) -> 1 | O36: =IF(LOWER(L36)=LOWER(Kappa!Y38),1,0) -> 0
A37: RFI for AI Services | B37: TBS Canada | C37: https://buyandsell.gc.ca/cds/public/2018/06/28/05baa93c08b6f2d3000855170f831066/ABES.PROD.PW__EE.B017.E33657.EBSU000.PDF | G37: Canada | H37: 28/06/2018 | I37: national authority | L37: =IF(ISNUMBER(SEARCH(",",I37)),"multistakeholders",lower(I37)) -> national authority | M37: =IF(LOWER(L37)=LOWER(Matthieu!M37),1,0) -> 1 | N37: =IF(LOWER(L37)=LOWER(Aina!N37),1,0) -> 1 | O37: =IF(LOWER(L37)=LOWER(Kappa!Y39),1,0) -> 1
A38: Beyond pilots: sustainable implementation of AI in public services | B38: European Commission (Joint Research Centre, AI Watch) | C38: https://publications.jrc.ec.europa.eu/repository/bitstream/JRC126665/jrc126665_sustainable_implementation_of_ai_in_public_services_technical-report_v2.pdf | G38: EU | H38: 2021 | I38: international organisation, academia | L38: =IF(ISNUMBER(SEARCH(",",I38)),"multistakeholders",lower(I38)) -> multistakeholders | M38: =IF(LOWER(L38)=LOWER(Matthieu!M38),1,0) -> 0 | N38: =IF(LOWER(L38)=LOWER(Aina!N38),1,0) -> 1 | O38: =IF(LOWER(L38)=LOWER(Kappa!Y40),1,0) -> 0
A39: Open letter: Civil society call for the introduction of red lines in the upcoming European Commission proposal on Artificial Intelligence | B39: European Digital Rights (EDRi) | C39: https://edri.org/wp-content/uploads/2021/01/EDRi-open-letter-AI-red-lines.pdf | G39: Belgium | H39: 12/01/2021 | I39: civil society, academia | L39: =IF(ISNUMBER(SEARCH(",",I39)),"multistakeholders",lower(I39)) -> multistakeholders | M39: =IF(LOWER(L39)=LOWER(Matthieu!M39),1,0) -> 0 | N39: =IF(LOWER(L39)=LOWER(Aina!N39),1,0) -> 0 | O39: =IF(LOWER(L39)=LOWER(Kappa!Y41),1,0) -> 0
A40: Governance Principles for a New Generation of Artificial Intelligence: Develop Responsible Artificial Intelligence | B40: National New Generation Artificial Intelligence Governance Expert Committee | C40: https://www.newamerica.org/cybersecurity-initiative/digichina/blog/translation-chinese-expert-group-offers-governance-principles-responsible-ai/ | G40: China | H40: 2019 | I40: national authority, academia | L40: =IF(ISNUMBER(SEARCH(",",I40)),"multistakeholders",lower(I40)) -> multistakeholders | M40: =IF(LOWER(L40)=LOWER(Matthieu!M40),1,0) -> 0 | N40: =IF(LOWER(L40)=LOWER(Aina!N40),1,0) -> 0 | O40: =IF(LOWER(L40)=LOWER(Kappa!Y42),1,0) -> 0
A41: Principles for Responsible AI | B41: Women leading in AI | C41: https://womenleadinginai.org/wp-content/uploads/2019/02/WLiAI-Report-2019.pdf | D41: Ivana Bartoletti,Allison Gardner,Reema Patel,Emma Gibson,Liz Stocks,Samara Banno,Sanya Sheikh,Rebecca Geach,Holly Rafique | G41: UK | H41: 2019 | I41: civil society | L41: =IF(ISNUMBER(SEARCH(",",I41)),"multistakeholders",lower(I41)) -> civil society | M41: =IF(LOWER(L41)=LOWER(Matthieu!M41),1,0) -> 1 | N41: =IF(LOWER(L41)=LOWER(Aina!N41),1,0) -> 1 | O41: =IF(LOWER(L41)=LOWER(Kappa!Y43),1,0) -> 1
A42: Report with recommendations to the Commission on a framework of ethical aspects of artificial intelligence, robotics and related technologies | B42: European Parliament | C42: https://www.europarl.europa.eu/doceo/document/A-9-2020-0186_EN.pdf | G42: EU | H42: 08/10/2020 | I42: international organisation | L42: =IF(ISNUMBER(SEARCH(",",I42)),"multistakeholders",lower(I42)) -> international organisation | M42: =IF(LOWER(L42)=LOWER(Matthieu!M42),1,0) -> 1 | N42: =IF(LOWER(L42)=LOWER(Aina!N42),1,0) -> 1 | O42: =IF(LOWER(L42)=LOWER(Kappa!Y44),1,0) -> 1
...

Sheet Aina
A1: Title | B1: Institution | C1: URL | G1: Country | H1: Date | I1: Sector | J1: unsure? | K1: justification (when unsure / if needed for discussion) | O1: Matthieu | P1: Maria | Q1: Simon
